<?xml version="1.0" ?>
<!-- =================================================================================== -->
<!-- |    This document was autogenerated by xacro from hermes.urdf.xacro              | -->
<!-- |    EDITING THIS FILE BY HAND IS NOT RECOMMENDED                                 | -->
<!-- =================================================================================== -->
<robot name="hermes">
  <!-- Materials -->
  <material name="blue">
    <color rgba="0 0 0.8 1"/>
  </material>
  <material name="black">
    <color rgba="0 0 0 1"/>
  </material>
  <material name="white">
    <color rgba="1 1 1 1"/>
  </material>
  <material name="grey">
    <color rgba="0.8 0.8 0.8 1"/>
  </material>
  <!-- Base link -->
  <link name="base_link"/>
  <joint name="dummy_joint" type="fixed">
    <parent link="base_link"/>
    <child link="frame"/>
    <origin rpy="0 -1.571 0" xyz="0 0 0.8"/>
  </joint>
  <!-- Frame -->
  <link name="frame">
    <visual>
      <origin rpy="0.0 0 0" xyz="0 0 0"/>
      <geometry>
        <mesh filename="package://salvos_gz/models/hermes/meshes/hermes_mesh_scaled.stl"/>
      </geometry>
      <material name="grey"/>
    </visual>
    <collision>
      <origin rpy="0.0 0 0" xyz="0 0 0"/>
      <geometry>
        <mesh filename="package://salvos_gz/models/hermes/meshes/hermes_mesh_scaled.stl"/>
      </geometry>
    </collision>
    <inertial>
      <origin rpy="0 0 0" xyz="0 0 0"/>
      <mass value="2.637"/>
      <inertia ixx="47.090" ixy="0.0" ixz="0.0" iyy="87.969" iyz="0.0" izz="118.937"/>
    </inertial>
  </link>
  <!-- Nose rotor -->
  <link name="nose_rotor">
    <visual>
      <origin rpy="0 0 0" xyz="0 0 0"/>
      <geometry>
        <cylinder length="1.2" radius="0.05"/>
      </geometry>
      <material name="blue"/>
    </visual>
    <collision>
      <origin rpy="0.0 0 0" xyz="0 0 0"/>
      <geometry>
        <cylinder length="1.2" radius="0.05"/>
      </geometry>
    </collision>
    <inertial>
      <origin rpy="0 0 0" xyz="0 0 0"/>
      <mass value="0.1265424"/>
      <inertia ixx="0.1185" ixy="0.0" ixz="0.0" iyy="0.1170" iyz="0.009964" izz="0.001558"/>
    </inertial>
  </link>
  <joint name="nose_rotor_joint" type="continuous">
    <parent link="frame"/>
    <child link="nose_rotor"/>
    <origin rpy="0 0 0" xyz="1 0 0"/>
    <axis xyz="-1 0 0"/>
    <limit effort="10" velocity="10000"/>
    <dynamics damping="0.002" friction="0.0005"/>
  </joint>
  <!--
    <joint name="nose_rotor_joint" type="continuous">
      <parent link="frame"/>
      <child link="nose_rotor"/>
      <origin xyz="1 0 0" rpy="0 1.571 3.14159"/>
      <axis xyz="0 0 1"/>
      <limit lower="0" upper="0" effort="10" velocity="600"/>
      <dynamics damping="0.002" friction="0.0005"/>
    </joint>
    -->
  <!-- Front-left rotor -->
  <link name="fl_rotor">
    <visual>
      <origin rpy="0 0 0" xyz="0 0 0"/>
      <geometry>
        <cylinder length="1.2" radius="0.05"/>
      </geometry>
      <material name="blue"/>
    </visual>
    <collision>
      <origin rpy="0.0 0 0" xyz="0 0 0"/>
      <geometry>
        <cylinder length="1.2" radius="0.05"/>
      </geometry>
    </collision>
    <inertial>
      <origin rpy="0 0 0" xyz="0 0 0"/>
      <mass value="0.1265424"/>
      <inertia ixx="0.1185" ixy="0.0" ixz="0.0" iyy="0.1170" iyz="0.009964" izz="0.001558"/>
    </inertial>
  </link>
  <joint name="fl_rotor_joint" type="continuous">
    <parent link="frame"/>
    <child link="fl_rotor"/>
    <origin rpy="0 0 0" xyz="0.5 0.81 0.81"/>
    <axis xyz="-1 0 0"/>
    <limit effort="10" velocity="10000"/>
    <dynamics damping="0.002" friction="0.0005"/>
  </joint>
  <!-- Front-right rotor -->
  <link name="fr_rotor">
    <visual>
      <origin rpy="0 0 0" xyz="0 0 0"/>
      <geometry>
        <cylinder length="1.2" radius="0.05"/>
      </geometry>
      <material name="blue"/>
    </visual>
    <collision>
      <origin rpy="0.0 0 0" xyz="0 0 0"/>
      <geometry>
        <cylinder length="1.2" radius="0.05"/>
      </geometry>
    </collision>
    <inertial>
      <origin rpy="0 0 0" xyz="0 0 0"/>
      <mass value="0.1265424"/>
      <inertia ixx="0.1185" ixy="0.0" ixz="0.0" iyy="0.1170" iyz="0.009964" izz="0.001558"/>
    </inertial>
  </link>
  <joint name="fr_rotor_joint" type="continuous">
    <parent link="frame"/>
    <child link="fr_rotor"/>
    <origin rpy="0 0 0" xyz="0.5 -0.88 0.88"/>
    <axis xyz="-1 0 0"/>
    <limit effort="10" velocity="10000"/>
    <dynamics damping="0.002" friction="0.0005"/>
  </joint>
  <!-- Rear-left rotor -->
  <link name="rl_rotor">
    <visual>
      <origin rpy="0 0 0" xyz="0 0 0"/>
      <geometry>
        <cylinder length="1.2" radius="0.05"/>
      </geometry>
      <material name="blue"/>
    </visual>
    <collision>
      <origin rpy="0.0 0 0" xyz="0 0 0"/>
      <geometry>
        <cylinder length="1.2" radius="0.05"/>
      </geometry>
    </collision>
    <inertial>
      <origin rpy="0 0 0" xyz="0 0 0"/>
      <mass value="0.1265424"/>
      <inertia ixx="0.1185" ixy="0.0" ixz="0.0" iyy="0.1170" iyz="0.009964" izz="0.001558"/>
    </inertial>
  </link>
  <joint name="rl_rotor_joint" type="continuous">
    <parent link="frame"/>
    <child link="rl_rotor"/>
    <origin rpy="0 0 0" xyz="0.5 -0.93 -0.93"/>
    <axis xyz="-1 0 0"/>
    <limit effort="10" velocity="10000"/>
    <dynamics damping="0.002" friction="0.0005"/>
  </joint>
  <!-- Rear-right rotor -->
  <link name="rr_rotor">
    <visual>
      <origin rpy="0 0 0" xyz="0 0 0"/>
      <geometry>
        <cylinder length="1.2" radius="0.05"/>
      </geometry>
      <material name="blue"/>
    </visual>
    <collision>
      <origin rpy="0.0 0 0" xyz="0 0 0"/>
      <geometry>
        <cylinder length="1.2" radius="0.05"/>
      </geometry>
    </collision>
    <inertial>
      <origin rpy="0 0 0" xyz="0 0 0"/>
      <mass value="0.1265424"/>
      <inertia ixx="0.1185" ixy="0.0" ixz="0.0" iyy="0.1170" iyz="0.009964" izz="0.001558"/>
    </inertial>
  </link>
  <joint name="rr_rotor_joint" type="continuous">
    <parent link="frame"/>
    <child link="rr_rotor"/>
    <origin rpy="0 0 0" xyz="0.5 0.93 -0.93"/>
    <axis xyz="-1 0 0"/>
    <limit effort="10" velocity="10000"/>
    <dynamics damping="0.002" friction="0.0005"/>
  </joint>
  <gazebo>
    <!-- Nose rotor -->
    <plugin filename="libgz-sim-joint-controller-system.so" name="gz::sim::systems::JointController">
      <joint_name>nose_rotor_joint</joint_name>
      <topic>/model/hermes/joint/nose_rotor_joint/cmd_vel</topic>
    </plugin>
    <!-- Front-left rotor -->
    <plugin filename="libgz-sim-joint-controller-system.so" name="gz::sim::systems::JointController">
      <joint_name>fl_rotor_joint</joint_name>
      <topic>/model/hermes/joint/fl_rotor_joint/cmd_vel</topic>
    </plugin>
    <!-- Front-right rotor -->
    <plugin filename="libgz-sim-joint-controller-system.so" name="gz::sim::systems::JointController">
      <joint_name>fr_rotor_joint</joint_name>
      <topic>/model/hermes/joint/fr_rotor_joint/cmd_vel</topic>
    </plugin>
    <!-- Rear-left rotor -->
    <plugin filename="libgz-sim-joint-controller-system.so" name="gz::sim::systems::JointController">
      <joint_name>rl_rotor_joint</joint_name>
      <topic>/model/hermes/joint/rl_rotor_joint/cmd_vel</topic>
    </plugin>
    <!-- Rear-right rotor -->
    <plugin filename="libgz-sim-joint-controller-system.so" name="gz::sim::systems::JointController">
      <joint_name>rr_rotor_joint</joint_name>
      <topic>/model/hermes/joint/rr_rotor_joint/cmd_vel</topic>
    </plugin>
    <plugin filename="gz-sim-multicopter-motor-model-system.so" name="gz::sim::systems::MulticopterMotorModel">
      <robotNamespace>hermes</robotNamespace>
      <!-- Nose rotor -->
      <motor>
        <jointName>nose_rotor_joint</jointName>
        <linkName>nose_rotor</linkName>
        <turningDirection>ccw</turningDirection>
        <motorConstant>0.0075</motorConstant>
        <!-- thrust coefficient -->
        <momentConstant>0.06</momentConstant>
        <commandSubTopic>gazebo/command/motor_speed</commandSubTopic>
        <motorNumber>0</motorNumber>
        <rotorDragCoefficient>2.5e-4</rotorDragCoefficient>
        <rollingMomentCoefficient>1e-6</rollingMomentCoefficient>
        <motorSpeedPubTopic>/hermes/motor_speed/m0</motorSpeedPubTopic>
        <rotorVelocitySlowdownSim>1</rotorVelocitySlowdownSim>
        <timeConstantUp>0.0125</timeConstantUp>
        <timeConstantDown>0.025</timeConstantDown>
        <maxRotVelocity>1200.0</maxRotVelocity>
        <motorType>velocity</motorType>
      </motor>
      <!-- Front-left rotor -->
      <motor>
        <jointName>fl_rotor_joint</jointName>
        <linkName>fl_rotor</linkName>
        <turningDirection>ccw</turningDirection>
        <motorConstant>0.0075</motorConstant>
        <!-- thrust coefficient -->
        <momentConstant>0.06</momentConstant>
        <commandSubTopic>gazebo/command/motor_speed</commandSubTopic>
        <motorNumber>1</motorNumber>
        <rotorDragCoefficient>2.5e-4</rotorDragCoefficient>
        <rollingMomentCoefficient>1e-6</rollingMomentCoefficient>
        <motorSpeedPubTopic>/hermes/motor_speed/m1</motorSpeedPubTopic>
        <rotorVelocitySlowdownSim>1</rotorVelocitySlowdownSim>
        <timeConstantUp>0.0125</timeConstantUp>
        <timeConstantDown>0.025</timeConstantDown>
        <maxRotVelocity>1200.0</maxRotVelocity>
        <motorType>velocity</motorType>
      </motor>
      <!-- Front-right rotor -->
      <motor>
        <jointName>fr_rotor_joint</jointName>
        <linkName>fr_rotor</linkName>
        <turningDirection>cw</turningDirection>
        <motorConstant>0.0075</motorConstant>
        <!-- thrust coefficient -->
        <momentConstant>0.06</momentConstant>
        <commandSubTopic>gazebo/command/motor_speed</commandSubTopic>
        <motorNumber>2</motorNumber>
        <rotorDragCoefficient>2.5e-4</rotorDragCoefficient>
        <rollingMomentCoefficient>1e-6</rollingMomentCoefficient>
        <motorSpeedPubTopic>/hermes/motor_speed/m2</motorSpeedPubTopic>
        <rotorVelocitySlowdownSim>1</rotorVelocitySlowdownSim>
        <timeConstantUp>0.0125</timeConstantUp>
        <timeConstantDown>0.025</timeConstantDown>
        <maxRotVelocity>1200.0</maxRotVelocity>
        <motorType>velocity</motorType>
      </motor>
      <!-- Rear-left rotor -->
      <motor>
        <jointName>rl_rotor_joint</jointName>
        <linkName>rl_rotor</linkName>
        <turningDirection>cw</turningDirection>
        <motorConstant>0.0075</motorConstant>
        <!-- thrust coefficient -->
        <momentConstant>0.06</momentConstant>
        <commandSubTopic>gazebo/command/motor_speed</commandSubTopic>
        <motorNumber>3</motorNumber>
        <rotorDragCoefficient>2.5e-4</rotorDragCoefficient>
        <rollingMomentCoefficient>1e-6</rollingMomentCoefficient>
        <motorSpeedPubTopic>/hermes/motor_speed/m3</motorSpeedPubTopic>
        <rotorVelocitySlowdownSim>1</rotorVelocitySlowdownSim>
        <timeConstantUp>0.0125</timeConstantUp>
        <timeConstantDown>0.025</timeConstantDown>
        <maxRotVelocity>1200.0</maxRotVelocity>
        <motorType>velocity</motorType>
      </motor>
      <!-- Rear-right rotor -->
      <motor>
        <jointName>rr_rotor_joint</jointName>
        <linkName>rr_rotor</linkName>
        <turningDirection>ccw</turningDirection>
        <motorConstant>0.0075</motorConstant>
        <!-- thrust coefficient -->
        <momentConstant>0.06</momentConstant>
        <commandSubTopic>gazebo/command/motor_speed</commandSubTopic>
        <motorNumber>4</motorNumber>
        <rotorDragCoefficient>2.5e-4</rotorDragCoefficient>
        <rollingMomentCoefficient>1e-6</rollingMomentCoefficient>
        <motorSpeedPubTopic>/hermes/motor_speed/m4</motorSpeedPubTopic>
        <rotorVelocitySlowdownSim>1</rotorVelocitySlowdownSim>
        <timeConstantUp>0.0125</timeConstantUp>
        <timeConstantDown>0.025</timeConstantDown>
        <maxRotVelocity>1200.0</maxRotVelocity>
        <motorType>velocity</motorType>
      </motor>
    </plugin>
  </gazebo>
</robot>
